<sdf version='1.4'>
  <world name='default'>
    <model name='ground_plane'>
      <static>1</static>
      <link name='link'>
        <collision name='collision'>
          <geometry>
            <plane>
              <normal>0 0 1</normal>
              <size>100 100</size>
            </plane>
          </geometry>
          <surface>
            <friction>
              <ode>
                <mu>100</mu>
                <mu2>50</mu2>
              </ode>
            </friction>
            <bounce/>
            <contact>
              <ode/>
            </contact>
          </surface>
          <max_contacts>10</max_contacts>
        </collision>
        <visual name='visual'>
          <cast_shadows>0</cast_shadows>
          <geometry>
            <plane>
              <normal>0 0 1</normal>
              <size>100 100</size>
            </plane>
          </geometry>
          <material>
            <script>
              <uri>file://media/materials/scripts/gazebo.material</uri>
              <name>Gazebo/Grey</name>
            </script>
          </material>
        </visual>
        <velocity_decay>
          <linear>0</linear>
          <angular>0</angular>
        </velocity_decay>
        <self_collide>0</self_collide>
        <kinematic>0</kinematic>
        <gravity>1</gravity>
      </link>
    </model>
    <light name='sun' type='directional'>
      <cast_shadows>1</cast_shadows>
      <pose>0 0 10 0 -0 0</pose>
      <diffuse>0.8 0.8 0.8 1</diffuse>
      <specular>0.2 0.2 0.2 1</specular>
      <attenuation>
        <range>1000</range>
        <constant>0.9</constant>
        <linear>0.01</linear>
        <quadratic>0.001</quadratic>
      </attenuation>
      <direction>-0.5 0.1 -0.9</direction>
    </light>
    <physics type='ode'>
      <real_time_update_rate>1000</real_time_update_rate>
      <gravity>0 0 -9.81</gravity>
      <max_step_size>0.001</max_step_size>
      <real_time_factor>1</real_time_factor>
    </physics>
    <scene>
      <ambient>0.4 0.4 0.4 1</ambient>
      <background>0.7 0.7 0.7 1</background>
      <shadows>1</shadows>
    </scene>
    <spherical_coordinates>
      <surface_model>EARTH_WGS84</surface_model>
      <latitude_deg>0</latitude_deg>
      <longitude_deg>0</longitude_deg>
      <elevation>0</elevation>
      <heading_deg>0</heading_deg>
    </spherical_coordinates>
    <model name='baxter'>
      <link name='base'>
        <pose>0 0 0 0 -0 0</pose>
        <inertial>
          <pose>1.93397e-07 1.09046e-22 3.46402e-06 0 -0 0</pose>
          <mass>96.2011</mass>
          <inertia>
            <ixx>6.91297</ixx>
            <ixy>0.00068017</ixy>
            <ixz>0.64779</ixz>
            <iyy>7.74978</iyy>
            <iyz>0.00434511</iyz>
            <izz>5.76418</izz>
          </inertia>
        </inertial>
        <collision name='base_collision_collision_head_link_1'>
          <pose>0.04 -0.04 0.75 0 -0 0</pose>
          <geometry>
            <sphere>
              <radius>0.22</radius>
            </sphere>
          </geometry>
          <max_contacts>10</max_contacts>
          <surface>
            <bounce/>
            <friction>
              <ode/>
            </friction>
            <contact>
              <ode/>
            </contact>
          </surface>
        </collision>
        <collision name='base_collision_collision_head_link_2'>
          <pose>0.04 0.04 0.75 0 -0 0</pose>
          <geometry>
            <sphere>
              <radius>0.22</radius>
            </sphere>
          </geometry>
          <max_contacts>10</max_contacts>
          <surface>
            <bounce/>
            <friction>
              <ode/>
            </friction>
            <contact>
              <ode/>
            </contact>
          </surface>
        </collision>
        <collision name='base_collision_pedestal'>
          <pose>0 0 0 0 -0 0</pose>
          <geometry>
            <mesh>
              <scale>1 1 1</scale>
              <uri>/home/ynazon1/Desktop/baxter_stuff/src/baxter_common/baxter_description/meshes/base/pedestal_link_collision.DAE</uri>
            </mesh>
          </geometry>
          <max_contacts>10</max_contacts>
          <surface>
            <bounce/>
            <friction>
              <ode/>
            </friction>
            <contact>
              <ode/>
            </contact>
          </surface>
        </collision>
        <collision name='base_collision_sonar_ring'>
          <pose>0.0947 0 0.817 0 -0 0</pose>
          <geometry>
            <sphere>
              <radius>0.001</radius>
            </sphere>
          </geometry>
          <surface>
            <contact>
              <ode/>
            </contact>
            <friction>
              <ode/>
            </friction>
            <bounce/>
          </surface>
          <max_contacts>10</max_contacts>
        </collision>
        <collision name='base_collision_torso'>
          <pose>0 0 0 0 -0 0</pose>
          <geometry>
            <mesh>
              <scale>1 1 1</scale>
              <uri>/home/ynazon1/Desktop/baxter_stuff/src/baxter_common/baxter_description/meshes/torso/base_link_collision.DAE</uri>
            </mesh>
          </geometry>
          <surface>
            <contact>
              <ode/>
            </contact>
            <friction>
              <ode/>
            </friction>
            <bounce/>
          </surface>
          <max_contacts>10</max_contacts>
        </collision>
        <visual name='base_visual_collision_head_link_1'>
          <pose>0.11 0 0.75 0 -0 0</pose>
          <geometry>
            <sphere>
              <radius>0.001</radius>
            </sphere>
          </geometry>
        </visual>
        <visual name='base_visual_collision_head_link_2'>
          <pose>0.11 0 0.75 0 -0 0</pose>
          <geometry>
            <sphere>
              <radius>0.001</radius>
            </sphere>
          </geometry>
        </visual>
        <visual name='base_visual_pedestal'>
          <pose>0 0 0 0 -0 0</pose>
          <geometry>
            <mesh>
              <scale>1 1 1</scale>
              <uri>/home/ynazon1/Desktop/baxter_stuff/src/baxter_common/baxter_description/meshes/base/PEDESTAL.DAE</uri>
            </mesh>
          </geometry>
        </visual>
        <visual name='base_visual_sonar_ring'>
          <pose>0.06 0 0.82653 0 -0 0</pose>
          <geometry>
            <cylinder>
              <length>0.01</length>
              <radius>0.085</radius>
            </cylinder>
          </geometry>
        </visual>
        <visual name='base_visual_torso'>
          <pose>0 0 0 0 -0 0</pose>
          <geometry>
            <mesh>
              <scale>1 1 1</scale>
              <uri>/home/ynazon1/Desktop/baxter_stuff/src/baxter_common/baxter_description/meshes/torso/base_link.DAE</uri>
            </mesh>
          </geometry>
        </visual>
        <velocity_decay>
          <linear>0</linear>
          <angular>0</angular>
        </velocity_decay>
        <gravity>1</gravity>
        <velocity_decay>
          <linear>0</linear>
          <angular>0</angular>
        </velocity_decay>
        <self_collide>0</self_collide>
        <sensor name='sonar' type='ray'>
          <ray>
            <scan>
              <horizontal>
                <samples>12</samples>
                <resolution>1</resolution>
                <min_angle>-3.14</min_angle>
                <max_angle>3.14</max_angle>
              </horizontal>
              <vertical>
                <samples>2</samples>
                <resolution>1</resolution>
                <min_angle>-0.001</min_angle>
                <max_angle>0</max_angle>
              </vertical>
            </scan>
            <range>
              <min>0.05</min>
              <max>50</max>
            </range>
          </ray>
          <plugin name='sonar_plugin' filename='libgazebo_ros_block_laser.so'>
            <gaussianNoise>0.00</gaussianNoise>
            <alwaysOn>true</alwaysOn>
            <updateRate>100.0</updateRate>
            <topicName>/robot/sonar/head_sonar/state</topicName>
            <frameName>sonar_ring</frameName>
            <robotNamespace>/</robotNamespace>
          </plugin>
          <always_on>1</always_on>
          <update_rate>100</update_rate>
          <pose>0.0947 0 0.817 0 -0 0</pose>
        </sensor>
        <kinematic>0</kinematic>
      </link>
      <link name='head'>
        <pose>0.06 0 0.686 0 -0 0</pose>
        <inertial>
          <pose>0.0546769 1.41752e-18 4.85084e-06 0 -0 0</pose>
          <mass>0.988238</mass>
          <inertia>
            <ixx>0.00620194</ixx>
            <ixy>0.000202093</ixy>
            <ixz>0.000495898</ixz>
            <iyy>0.010977</iyy>
            <iyz>-0.00109806</iyz>
            <izz>0.00983914</izz>
          </inertia>
        </inertial>
        <collision name='head_collision'>
          <pose>0 0 0 0 -0 0</pose>
          <geometry>
            <sphere>
              <radius>0.001</radius>
            </sphere>
          </geometry>
          <max_contacts>10</max_contacts>
          <surface>
            <bounce/>
            <friction>
              <ode/>
            </friction>
            <contact>
              <ode/>
            </contact>
          </surface>
        </collision>
        <collision name='head_collision_screen'>
          <pose>0.1227 0 0 1.75057 3.87602e-18 1.5708</pose>
          <geometry>
            <sphere>
              <radius>0.001</radius>
            </sphere>
          </geometry>
          <max_contacts>10</max_contacts>
          <surface>
            <bounce/>
            <friction>
              <ode/>
            </friction>
            <contact>
              <ode/>
            </contact>
          </surface>
        </collision>
        <visual name='head_visual'>
          <pose>0 0 0.00953 0 -0 0</pose>
          <geometry>
            <mesh>
              <scale>1 1 1</scale>
              <uri>/home/ynazon1/Desktop/baxter_stuff/src/baxter_common/baxter_description/meshes/head/H0.DAE</uri>
            </mesh>
          </geometry>
        </visual>
        <visual name='head_visual_display'>
          <pose>0.119839 1.40051e-14 -0.0157421 2.01237 -5.22585e-17 1.5708</pose>
          <geometry>
            <box>
              <size>0.218 0.16 0.001</size>
            </box>
          </geometry>
          <plugin name='screen_video_controller' filename='libgazebo_ros_video.so'>
            <height>600</height>
            <width>1024</width>
            <topicName>/robot/xdisplay</topicName>
            <robotNamespace>/</robotNamespace>
          </plugin>
        </visual>
        <visual name='head_visual_screen'>
          <pose>0.0868552 1.75517e-13 -0.00317182 1.5708 0.179774 8.02011e-14</pose>
          <geometry>
            <mesh>
              <scale>1 1 1</scale>
              <uri>/home/ynazon1/Desktop/baxter_stuff/src/baxter_common/baxter_description/meshes/head/H1.DAE</uri>
            </mesh>
          </geometry>
        </visual>
        <velocity_decay>
          <linear>0</linear>
          <angular>0</angular>
        </velocity_decay>
        <sensor name='head_camera' type='camera'>
          <update_rate>30</update_rate>
          <camera name='head_camera'>
            <pose>0 0.21 0 1.82851e-17 -0.8 -1.5708</pose>
            <horizontal_fov>1.39626</horizontal_fov>
            <image>
              <width>800</width>
              <height>800</height>
              <format>R8G8B8</format>
            </image>
            <clip>
              <near>0.02</near>
              <far>300</far>
            </clip>
            <noise>
              <type>gaussian</type>
              <mean>0</mean>
              <stddev>0.007</stddev>
            </noise>
          </camera>
          <plugin name='camera_controller' filename='libgazebo_ros_camera.so'>
            <alwaysOn>true</alwaysOn>
            <updateRate>0.0</updateRate>
            <cameraName>head_camera</cameraName>
            <imageTopicName>image</imageTopicName>
            <cameraInfoTopicName>camera_info</cameraInfoTopicName>
            <frameName>head_camera</frameName>
            <hackBaseline>0.07</hackBaseline>
            <distortionK1>0.0</distortionK1>
            <distortionK2>0.0</distortionK2>
            <distortionK3>0.0</distortionK3>
            <distortionT1>0.0</distortionT1>
            <distortionT2>0.0</distortionT2>
            <robotNamespace>/cameras</robotNamespace>
          </plugin>
          <pose>0.12839 0 0.06368 1.75057 3.87602e-18 1.5708</pose>
        </sensor>
        <gravity>1</gravity>
        <velocity_decay>
          <linear>0</linear>
          <angular>0</angular>
        </velocity_decay>
        <self_collide>0</self_collide>
        <kinematic>0</kinematic>
      </link>
      <joint name='head_pan' type='revolute'>
        <child>head</child>
        <parent>base</parent>
        <axis>
          <xyz>0 0 1</xyz>
          <limit>
            <lower>-1.5708</lower>
            <upper>1.5708</upper>
            <effort>50000</effort>
            <velocity>10000</velocity>
          </limit>
          <dynamics>
            <damping>0.7</damping>
          </dynamics>
        </axis>
        <physics>
          <ode>
            <implicit_spring_damper>1</implicit_spring_damper>
            <cfm_damping>1</cfm_damping>
            <limit>
              <cfm>0</cfm>
              <erp>0.2</erp>
            </limit>
          </ode>
        </physics>
      </joint>
      <link name='left_upper_shoulder'>
        <pose>0.0640272 0.259027 0.129626 0 -0 0.7854</pose>
        <inertial>
          <pose>0.01783 0.00086 0.19127 0 -0 0</pose>
          <mass>5.70044</mass>
          <inertia>
            <ixx>0.047091</ixx>
            <ixy>0.000127876</ixy>
            <ixz>0.0061487</ixz>
            <iyy>0.0376698</iyy>
            <iyz>0.000780869</iyz>
            <izz>0.0359599</izz>
          </inertia>
        </inertial>
        <collision name='left_upper_shoulder_collision'>
          <pose>0 0 0.1361 0 -0 0</pose>
          <geometry>
            <cylinder>
              <length>0.2722</length>
              <radius>0.06</radius>
            </cylinder>
          </geometry>
          <max_contacts>10</max_contacts>
          <surface>
            <bounce/>
            <friction>
              <ode/>
            </friction>
            <contact>
              <ode/>
            </contact>
          </surface>
        </collision>
        <visual name='left_upper_shoulder_visual'>
          <pose>0 0 0 0 -0 0</pose>
          <geometry>
            <mesh>
              <scale>1 1 1</scale>
              <uri>/home/ynazon1/Desktop/baxter_stuff/src/baxter_common/baxter_description/meshes/upper_shoulder/S0.DAE</uri>
            </mesh>
          </geometry>
        </visual>
        <velocity_decay>
          <linear>0</linear>
          <angular>0</angular>
        </velocity_decay>
        <self_collide>0</self_collide>
        <gravity>0</gravity>
        <kinematic>0</kinematic>
      </link>
      <joint name='left_s0' type='revolute'>
        <child>left_upper_shoulder</child>
        <parent>base</parent>
        <axis>
          <xyz>0 0 1</xyz>
          <limit>
            <lower>-1.70168</lower>
            <upper>1.70168</upper>
            <effort>50</effort>
            <velocity>1.5</velocity>
          </limit>
          <dynamics>
            <damping>0.7</damping>
          </dynamics>
        </axis>
        <physics>
          <ode>
            <implicit_spring_damper>1</implicit_spring_damper>
            <cfm_damping>1</cfm_damping>
            <limit>
              <cfm>0</cfm>
              <erp>0.2</erp>
            </limit>
          </ode>
        </physics>
      </joint>
      <link name='left_lower_shoulder'>
        <pose>0.112818 0.307818 0.399976 -1.5708 -1.76183e-17 0.7854</pose>
        <inertial>
          <pose>0.0684512 0.00268992 -0.00528984 0 -0 0</pose>
          <mass>3.22708</mass>
          <inertia>
            <ixx>0.0117521</ixx>
            <ixy>-0.000300954</ixy>
            <ixz>0.00207674</ixz>
            <iyy>0.0278861</iyy>
            <iyz>-0.000188219</iyz>
            <izz>0.0207877</izz>
          </inertia>
        </inertial>
        <collision name='left_lower_shoulder_collision'>
          <pose>0 0 0 0 -0 0</pose>
          <geometry>
            <cylinder>
              <length>0.12</length>
              <radius>0.06</radius>
            </cylinder>
          </geometry>
          <max_contacts>10</max_contacts>
          <surface>
            <bounce/>
            <friction>
              <ode/>
            </friction>
            <contact>
              <ode/>
            </contact>
          </surface>
        </collision>
        <collision name='left_lower_shoulder_collision_left_upper_elbow_visual'>
          <pose>0.2435 -6.68384e-13 6.68382e-13 1.5708 -1.69705e-16 1.5708</pose>
          <geometry>
            <cylinder>
              <length>0.273</length>
              <radius>0.06</radius>
            </cylinder>
          </geometry>
          <max_contacts>10</max_contacts>
          <surface>
            <bounce/>
            <friction>
              <ode/>
            </friction>
            <contact>
              <ode/>
            </contact>
          </surface>
        </collision>
        <visual name='left_lower_shoulder_visual'>
          <pose>0 0 0 0 -0 0</pose>
          <geometry>
            <mesh>
              <scale>1 1 1</scale>
              <uri>/home/ynazon1/Desktop/baxter_stuff/src/baxter_common/baxter_description/meshes/lower_shoulder/S1.DAE</uri>
            </mesh>
          </geometry>
        </visual>
        <velocity_decay>
          <linear>0</linear>
          <angular>0</angular>
        </velocity_decay>
        <self_collide>0</self_collide>
        <gravity>0</gravity>
        <kinematic>0</kinematic>
      </link>
      <joint name='left_s1' type='revolute'>
        <child>left_lower_shoulder</child>
        <parent>left_upper_shoulder</parent>
        <axis>
          <xyz>-0.707108 0.707105 0</xyz>
          <limit>
            <lower>-2.147</lower>
            <upper>1.047</upper>
            <effort>100</effort>
            <velocity>1.5</velocity>
          </limit>
          <dynamics>
            <damping>0.7</damping>
          </dynamics>
        </axis>
        <physics>
          <ode>
            <implicit_spring_damper>1</implicit_spring_damper>
            <cfm_damping>1</cfm_damping>
            <limit>
              <cfm>0</cfm>
              <erp>0.2</erp>
            </limit>
          </ode>
        </physics>
      </joint>
      <link name='left_upper_elbow'>
        <pose>0.184942 0.379943 0.399976 -2.35619 1.57079 -1.57078</pose>
        <inertial>
          <pose>-0.00276 0.00132 0.18086 0 -0 0</pose>
          <mass>4.31272</mass>
          <inertia>
            <ixx>0.0266173</ixx>
            <ixy>0.000292706</ixy>
            <ixz>0.0039219</ixz>
            <iyy>0.0284436</iyy>
            <iyz>0.00108389</iyz>
            <izz>0.0124801</izz>
          </inertia>
        </inertial>
        <collision name='left_upper_elbow_collision'>
          <pose>0 0 -0.0535 0 -0 0</pose>
          <geometry>
            <cylinder>
              <length>0.107</length>
              <radius>0.06</radius>
            </cylinder>
          </geometry>
          <max_contacts>10</max_contacts>
          <surface>
            <bounce/>
            <friction>
              <ode/>
            </friction>
            <contact>
              <ode/>
            </contact>
          </surface>
        </collision>
        <visual name='left_upper_elbow_visual'>
          <pose>0 0 0 0 -0 0</pose>
          <geometry>
            <mesh>
              <scale>1 1 1</scale>
              <uri>/home/ynazon1/Desktop/baxter_stuff/src/baxter_common/baxter_description/meshes/upper_elbow/E0.DAE</uri>
            </mesh>
          </geometry>
        </visual>
        <velocity_decay>
          <linear>0</linear>
          <angular>0</angular>
        </velocity_decay>
        <self_collide>0</self_collide>
        <gravity>0</gravity>
        <kinematic>0</kinematic>
      </link>
      <joint name='left_e0' type='revolute'>
        <child>left_upper_elbow</child>
        <parent>left_lower_shoulder</parent>
        <axis>
          <xyz>0.707105 0.707108 0</xyz>
          <limit>
            <lower>-3.05418</lower>
            <upper>3.05418</upper>
            <effort>50</effort>
            <velocity>1.5</velocity>
          </limit>
          <dynamics>
            <damping>0.7</damping>
          </dynamics>
        </axis>
        <physics>
          <ode>
            <implicit_spring_damper>1</implicit_spring_damper>
            <cfm_damping>1</cfm_damping>
            <limit>
              <cfm>0</cfm>
              <erp>0.2</erp>
            </limit>
          </ode>
        </physics>
      </joint>
      <link name='left_lower_elbow'>
        <pose>0.370501 0.565502 0.330976 -1.5708 -1.6263e-16 0.7854</pose>
        <inertial>
          <pose>0.026113 0.00158992 -0.0111695 0 -0 0</pose>
          <mass>2.07216</mass>
          <inertia>
            <ixx>0.00711585</ixx>
            <ixy>0.000360372</ixy>
            <ixz>0.00074588</ixz>
            <iyy>0.0131827</iyy>
            <iyz>-0.000196632</iyz>
            <izz>0.00926891</izz>
          </inertia>
        </inertial>
        <collision name='left_lower_elbow_collision'>
          <pose>0 0 0 0 -0 0</pose>
          <geometry>
            <cylinder>
              <length>0.1</length>
              <radius>0.06</radius>
            </cylinder>
          </geometry>
          <max_contacts>10</max_contacts>
          <surface>
            <bounce/>
            <friction>
              <ode/>
            </friction>
            <contact>
              <ode/>
            </contact>
          </surface>
        </collision>
        <collision name='left_lower_elbow_collision_left_upper_forearm_visual'>
          <pose>0.224 -6.65935e-13 6.6594e-13 1.5708 -1.69705e-16 1.5708</pose>
          <geometry>
            <cylinder>
              <length>0.272</length>
              <radius>0.06</radius>
            </cylinder>
          </geometry>
          <max_contacts>10</max_contacts>
          <surface>
            <bounce/>
            <friction>
              <ode/>
            </friction>
            <contact>
              <ode/>
            </contact>
          </surface>
        </collision>
        <visual name='left_lower_elbow_visual'>
          <pose>0 0 0 0 -0 0</pose>
          <geometry>
            <mesh>
              <scale>1 1 1</scale>
              <uri>/home/ynazon1/Desktop/baxter_stuff/src/baxter_common/baxter_description/meshes/lower_elbow/E1.DAE</uri>
            </mesh>
          </geometry>
        </visual>
        <velocity_decay>
          <linear>0</linear>
          <angular>0</angular>
        </velocity_decay>
        <self_collide>0</self_collide>
        <gravity>0</gravity>
        <kinematic>0</kinematic>
      </link>
      <joint name='left_e1' type='revolute'>
        <child>left_lower_elbow</child>
        <parent>left_upper_elbow</parent>
        <axis>
          <xyz>-0.707108 0.707105 0</xyz>
          <limit>
            <lower>-0.05</lower>
            <upper>2.618</upper>
            <effort>50</effort>
            <velocity>1.5</velocity>
          </limit>
          <dynamics>
            <damping>0.7</damping>
          </dynamics>
        </axis>
        <physics>
          <ode>
            <implicit_spring_damper>1</implicit_spring_damper>
            <cfm_damping>1</cfm_damping>
            <limit>
              <cfm>0</cfm>
              <erp>0.2</erp>
            </limit>
          </ode>
        </physics>
      </joint>
      <link name='left_upper_forearm'>
        <pose>0.44375 0.638751 0.330976 -2.03445 1.57079 -1.24905</pose>
        <inertial>
          <pose>-0.00168244 0.0045998 0.139519 0 -0 0</pose>
          <mass>2.24675</mass>
          <inertia>
            <ixx>0.0166775</ixx>
            <ixy>0.000184012</ixy>
            <ixz>0.000186469</ixz>
            <iyy>0.0167549</iyy>
            <iyz>-0.000647332</iyz>
            <izz>0.00374662</izz>
          </inertia>
        </inertial>
        <collision name='left_upper_forearm_collision'>
          <pose>0 0 -0.044 0 -0 0</pose>
          <geometry>
            <cylinder>
              <length>0.088</length>
              <radius>0.06</radius>
            </cylinder>
          </geometry>
          <max_contacts>10</max_contacts>
          <surface>
            <bounce/>
            <friction>
              <ode/>
            </friction>
            <contact>
              <ode/>
            </contact>
          </surface>
        </collision>
        <visual name='left_upper_forearm_visual'>
          <pose>0 0 0 0 -0 0</pose>
          <geometry>
            <mesh>
              <scale>1 1 1</scale>
              <uri>/home/ynazon1/Desktop/baxter_stuff/src/baxter_common/baxter_description/meshes/upper_forearm/W0.DAE</uri>
            </mesh>
          </geometry>
        </visual>
        <velocity_decay>
          <linear>0</linear>
          <angular>0</angular>
        </velocity_decay>
        <self_collide>0</self_collide>
        <gravity>0</gravity>
        <kinematic>0</kinematic>
      </link>
      <joint name='left_w0' type='revolute'>
        <child>left_upper_forearm</child>
        <parent>left_lower_elbow</parent>
        <axis>
          <xyz>0.707105 0.707108 0</xyz>
          <limit>
            <lower>-3.059</lower>
            <upper>3.059</upper>
            <effort>15</effort>
            <velocity>4</velocity>
          </limit>
          <dynamics>
            <damping>0.7</damping>
          </dynamics>
        </axis>
        <physics>
          <ode>
            <implicit_spring_damper>1</implicit_spring_damper>
            <cfm_damping>1</cfm_damping>
            <limit>
              <cfm>0</cfm>
              <erp>0.2</erp>
            </limit>
          </ode>
        </physics>
      </joint>
      <link name='left_lower_forearm'>
        <pose>0.635163 0.830166 0.320976 -1.5708 -1.6263e-16 0.7854</pose>
        <inertial>
          <pose>0.06041 0.00697 0.006 0 -0 0</pose>
          <mass>1.60979</mass>
          <inertia>
            <ixx>0.00387607</ixx>
            <ixy>-0.000443848</ixy>
            <ixz>-0.00021115</ixz>
            <iyy>0.00700538</iyy>
            <iyz>0.000153481</iyz>
            <izz>0.00552755</izz>
          </inertia>
        </inertial>
        <collision name='left_lower_forearm_collision'>
          <pose>0 0 0 0 -0 0</pose>
          <geometry>
            <cylinder>
              <length>0.1</length>
              <radius>0.06</radius>
            </cylinder>
          </geometry>
          <max_contacts>10</max_contacts>
          <surface>
            <bounce/>
            <friction>
              <ode/>
            </friction>
            <contact>
              <ode/>
            </contact>
          </surface>
        </collision>
        <visual name='left_lower_forearm_visual'>
          <pose>0 0 0 0 -0 0</pose>
          <geometry>
            <mesh>
              <scale>1 1 1</scale>
              <uri>/home/ynazon1/Desktop/baxter_stuff/src/baxter_common/baxter_description/meshes/lower_forearm/W1.DAE</uri>
            </mesh>
          </geometry>
        </visual>
        <velocity_decay>
          <linear>0</linear>
          <angular>0</angular>
        </velocity_decay>
        <self_collide>0</self_collide>
        <gravity>0</gravity>
        <kinematic>0</kinematic>
      </link>
      <joint name='left_w1' type='revolute'>
        <child>left_lower_forearm</child>
        <parent>left_upper_forearm</parent>
        <axis>
          <xyz>-0.707108 0.707105 0</xyz>
          <limit>
            <lower>-1.5708</lower>
            <upper>2.094</upper>
            <effort>15</effort>
            <velocity>4</velocity>
          </limit>
          <dynamics>
            <damping>0.7</damping>
          </dynamics>
        </axis>
        <physics>
          <ode>
            <implicit_spring_damper>1</implicit_spring_damper>
            <cfm_damping>1</cfm_damping>
            <limit>
              <cfm>0</cfm>
              <erp>0.2</erp>
            </limit>
          </ode>
        </physics>
      </joint>
      <link name='left_wrist'>
        <pose>0.71717 0.912173 0.320976 -1.89255 1.57079 -1.10714</pose>
        <inertial>
          <pose>0.00515172 0.000956882 0.0467434 0 -0 0</pose>
          <mass>0.54278</mass>
          <inertia>
            <ixx>0.00121873</ixx>
            <ixy>8.12598e-06</ixy>
            <ixz>-6.62108e-05</ixz>
            <iyy>0.00128054</iyy>
            <iyz>4.75609e-06</iyz>
            <izz>0.000555294</izz>
          </inertia>
        </inertial>
        <collision name='left_wrist_collision'>
          <pose>0 0 0 0 -0 0</pose>
          <geometry>
            <cylinder>
              <length>0.165</length>
              <radius>0.06</radius>
            </cylinder>
          </geometry>
          <max_contacts>10</max_contacts>
          <surface>
            <bounce/>
            <friction>
              <ode/>
            </friction>
            <contact>
              <ode/>
            </contact>
          </surface>
        </collision>
        <collision name='left_wrist_collision_left_hand'>
          <pose>0 0 0.09035 0 -0 0</pose>
          <geometry>
            <cylinder>
              <length>0.0464</length>
              <radius>0.04</radius>
            </cylinder>
          </geometry>
          <max_contacts>10</max_contacts>
          <surface>
            <bounce/>
            <friction>
              <ode/>
            </friction>
            <contact>
              <ode/>
            </contact>
          </surface>
        </collision>
        <visual name='left_wrist_visual'>
          <pose>0 0 0 0 -0 0</pose>
          <geometry>
            <mesh>
              <scale>1 1 1</scale>
              <uri>/home/ynazon1/Desktop/baxter_stuff/src/baxter_common/baxter_description/meshes/wrist/W2.DAE</uri>
            </mesh>
          </geometry>
        </visual>
        <visual name='left_wrist_visual_left_gripper'>
          <pose>0 0 0.13855 0 -0 0</pose>
          <geometry>
            <box>
              <size>0.01 0.01 0.01</size>
            </box>
          </geometry>
        </visual>
        <visual name='left_wrist_visual_left_gripper_base'>
          <pose>0 0 0.09355 0 -0 0</pose>
          <geometry>
            <box>
              <size>0.025 0.075 0.035</size>
            </box>
          </geometry>
        </visual>
        <visual name='left_wrist_visual_left_hand_accelerometer'>
          <pose>0.00198 0.000133 0.09895 0 -0 0</pose>
          <geometry>
            <box>
              <size>0.01 0.01 0.01</size>
            </box>
          </geometry>
        </visual>
        <visual name='left_wrist_visual_left_hand_camera'>
          <pose>0.03825 0.012 0.128905 0 0 -1.5708</pose>
          <geometry>
            <cylinder>
              <length>0.01</length>
              <radius>0.02</radius>
            </cylinder>
          </geometry>
        </visual>
        <visual name='left_wrist_visual_left_hand_range'>
          <pose>0.032 -0.020245 0.14235 -3.14158 -1.57079 1.57078</pose>
          <geometry>
            <box>
              <size>0.005 0.02 0.005</size>
            </box>
          </geometry>
        </visual>
        <velocity_decay>
          <linear>0</linear>
          <angular>0</angular>
        </velocity_decay>
        <sensor name='left_hand_camera' type='camera'>
          <update_rate>30</update_rate>
          <camera name='left_hand_camera'>
            <pose>0 0 0 2.65359e-06 -1.57079 1.57079</pose>
            <horizontal_fov>1.39626</horizontal_fov>
            <image>
              <width>800</width>
              <height>800</height>
              <format>R8G8B8</format>
            </image>
            <clip>
              <near>0.02</near>
              <far>300</far>
            </clip>
            <noise>
              <type>gaussian</type>
              <mean>0</mean>
              <stddev>0.007</stddev>
            </noise>
          </camera>
          <plugin name='camera_controller' filename='libgazebo_ros_camera.so'>
            <alwaysOn>true</alwaysOn>
            <updateRate>0.0</updateRate>
            <cameraName>left_hand_camera</cameraName>
            <imageTopicName>image</imageTopicName>
            <cameraInfoTopicName>camera_info</cameraInfoTopicName>
            <frameName>left_hand_camera</frameName>
            <hackBaseline>0.07</hackBaseline>
            <distortionK1>0.0</distortionK1>
            <distortionK2>0.0</distortionK2>
            <distortionK3>0.0</distortionK3>
            <distortionT1>0.0</distortionT1>
            <distortionT2>0.0</distortionT2>
            <robotNamespace>/cameras</robotNamespace>
          </plugin>
          <pose>0.03825 0.012 0.128905 0 0 -1.5708</pose>
        </sensor>
        <gravity>0</gravity>
        <velocity_decay>
          <linear>0</linear>
          <angular>0</angular>
        </velocity_decay>
        <self_collide>0</self_collide>
        <sensor name='ir_left' type='ray'>
          <ray>
            <scan>
              <horizontal>
                <samples>1</samples>
                <resolution>1</resolution>
                <min_angle>-0.5</min_angle>
                <max_angle>0.5</max_angle>
              </horizontal>
            </scan>
            <range>
              <min>0.004</min>
              <max>0.4</max>
            </range>
          </ray>
          <plugin name='plugin_4' filename='libgazebo_ros_laser.so'>
            <gaussianNoise>0.005</gaussianNoise>
            <alwaysOn>true</alwaysOn>
            <updateRate>100</updateRate>
            <topicName>/sim/laserscan/left_hand_range/state</topicName>
            <frameName>left_hand_range</frameName>
            <robotNamespace>/</robotNamespace>
          </plugin>
          <always_on>1</always_on>
          <update_rate>100</update_rate>
          <pose>0.032 -0.020245 0.14235 -3.14158 -1.57079 1.57078</pose>
        </sensor>
        <kinematic>0</kinematic>
      </link>
      <joint name='left_w2' type='revolute'>
        <child>left_wrist</child>
        <parent>left_lower_forearm</parent>
        <axis>
          <xyz>0.707105 0.707108 0</xyz>
          <limit>
            <lower>-3.059</lower>
            <upper>3.059</upper>
            <effort>15</effort>
            <velocity>4</velocity>
          </limit>
          <dynamics>
            <damping>0.7</damping>
          </dynamics>
        </axis>
        <physics>
          <ode>
            <implicit_spring_damper>1</implicit_spring_damper>
            <cfm_damping>1</cfm_damping>
            <limit>
              <cfm>0</cfm>
              <erp>0.2</erp>
            </limit>
          </ode>
        </physics>
      </joint>
      <link name='right_upper_shoulder'>
        <pose>0.0640272 -0.259027 0.129626 0 0 -0.7854</pose>
        <inertial>
          <pose>0.01783 0.00086 0.19127 0 -0 0</pose>
          <mass>5.70044</mass>
          <inertia>
            <ixx>0.047091</ixx>
            <ixy>0.000127876</ixy>
            <ixz>0.0061487</ixz>
            <iyy>0.0376698</iyy>
            <iyz>0.000780869</iyz>
            <izz>0.0359599</izz>
          </inertia>
        </inertial>
        <collision name='right_upper_shoulder_collision'>
          <pose>0 0 0.1361 0 -0 0</pose>
          <geometry>
            <cylinder>
              <length>0.2722</length>
              <radius>0.06</radius>
            </cylinder>
          </geometry>
          <max_contacts>10</max_contacts>
          <surface>
            <bounce/>
            <friction>
              <ode/>
            </friction>
            <contact>
              <ode/>
            </contact>
          </surface>
        </collision>
        <visual name='right_upper_shoulder_visual'>
          <pose>0 0 0 0 -0 0</pose>
          <geometry>
            <mesh>
              <scale>1 1 1</scale>
              <uri>/home/ynazon1/Desktop/baxter_stuff/src/baxter_common/baxter_description/meshes/upper_shoulder/S0.DAE</uri>
            </mesh>
          </geometry>
        </visual>
        <velocity_decay>
          <linear>0</linear>
          <angular>0</angular>
        </velocity_decay>
        <self_collide>0</self_collide>
        <gravity>0</gravity>
        <kinematic>0</kinematic>
      </link>
      <joint name='right_s0' type='revolute'>
        <child>right_upper_shoulder</child>
        <parent>base</parent>
        <axis>
          <xyz>0 0 1</xyz>
          <limit>
            <lower>-1.70168</lower>
            <upper>1.70168</upper>
            <effort>50</effort>
            <velocity>1.5</velocity>
          </limit>
          <dynamics>
            <damping>0.7</damping>
          </dynamics>
        </axis>
        <physics>
          <ode>
            <implicit_spring_damper>1</implicit_spring_damper>
            <cfm_damping>1</cfm_damping>
            <limit>
              <cfm>0</cfm>
              <erp>0.2</erp>
            </limit>
          </ode>
        </physics>
      </joint>
      <link name='right_lower_shoulder'>
        <pose>0.112818 -0.307818 0.399976 -1.5708 1.76183e-17 -0.7854</pose>
        <inertial>
          <pose>0.0684512 0.00268992 -0.00528984 0 -0 0</pose>
          <mass>3.22708</mass>
          <inertia>
            <ixx>0.0117521</ixx>
            <ixy>-0.000300954</ixy>
            <ixz>0.00207674</ixz>
            <iyy>0.0278861</iyy>
            <iyz>-0.000188219</iyz>
            <izz>0.0207877</izz>
          </inertia>
        </inertial>
        <collision name='right_lower_shoulder_collision'>
          <pose>0 0 0 0 -0 0</pose>
          <geometry>
            <cylinder>
              <length>0.12</length>
              <radius>0.06</radius>
            </cylinder>
          </geometry>
          <max_contacts>10</max_contacts>
          <surface>
            <bounce/>
            <friction>
              <ode/>
            </friction>
            <contact>
              <ode/>
            </contact>
          </surface>
        </collision>
        <collision name='right_lower_shoulder_collision_right_upper_elbow_visual'>
          <pose>0.2435 -6.68384e-13 6.68382e-13 1.5708 -1.69705e-16 1.5708</pose>
          <geometry>
            <cylinder>
              <length>0.273</length>
              <radius>0.06</radius>
            </cylinder>
          </geometry>
          <max_contacts>10</max_contacts>
          <surface>
            <bounce/>
            <friction>
              <ode/>
            </friction>
            <contact>
              <ode/>
            </contact>
          </surface>
        </collision>
        <visual name='right_lower_shoulder_visual'>
          <pose>0 0 0 0 -0 0</pose>
          <geometry>
            <mesh>
              <scale>1 1 1</scale>
              <uri>/home/ynazon1/Desktop/baxter_stuff/src/baxter_common/baxter_description/meshes/lower_shoulder/S1.DAE</uri>
            </mesh>
          </geometry>
        </visual>
        <velocity_decay>
          <linear>0</linear>
          <angular>0</angular>
        </velocity_decay>
        <self_collide>0</self_collide>
        <gravity>0</gravity>
        <kinematic>0</kinematic>
      </link>
      <joint name='right_s1' type='revolute'>
        <child>right_lower_shoulder</child>
        <parent>right_upper_shoulder</parent>
        <axis>
          <xyz>0.707108 0.707105 0</xyz>
          <limit>
            <lower>-2.147</lower>
            <upper>1.047</upper>
            <effort>100</effort>
            <velocity>1.5</velocity>
          </limit>
          <dynamics>
            <damping>0.7</damping>
          </dynamics>
        </axis>
        <physics>
          <ode>
            <implicit_spring_damper>1</implicit_spring_damper>
            <cfm_damping>1</cfm_damping>
            <limit>
              <cfm>0</cfm>
              <erp>0.2</erp>
            </limit>
          </ode>
        </physics>
      </joint>
      <link name='right_upper_elbow'>
        <pose>0.184942 -0.379943 0.399976 -2.35618 1.57079 -3.14158</pose>
        <inertial>
          <pose>-0.00276 0.00132 0.18086 0 -0 0</pose>
          <mass>4.31272</mass>
          <inertia>
            <ixx>0.0266173</ixx>
            <ixy>0.000292706</ixy>
            <ixz>0.0039219</ixz>
            <iyy>0.0284436</iyy>
            <iyz>0.00108389</iyz>
            <izz>0.0124801</izz>
          </inertia>
        </inertial>
        <collision name='right_upper_elbow_collision'>
          <pose>0 0 -0.0535 0 -0 0</pose>
          <geometry>
            <cylinder>
              <length>0.107</length>
              <radius>0.06</radius>
            </cylinder>
          </geometry>
          <max_contacts>10</max_contacts>
          <surface>
            <bounce/>
            <friction>
              <ode/>
            </friction>
            <contact>
              <ode/>
            </contact>
          </surface>
        </collision>
        <visual name='right_upper_elbow_visual'>
          <pose>0 0 0 0 -0 0</pose>
          <geometry>
            <mesh>
              <scale>1 1 1</scale>
              <uri>/home/ynazon1/Desktop/baxter_stuff/src/baxter_common/baxter_description/meshes/upper_elbow/E0.DAE</uri>
            </mesh>
          </geometry>
        </visual>
        <velocity_decay>
          <linear>0</linear>
          <angular>0</angular>
        </velocity_decay>
        <self_collide>0</self_collide>
        <gravity>0</gravity>
        <kinematic>0</kinematic>
      </link>
      <joint name='right_e0' type='revolute'>
        <child>right_upper_elbow</child>
        <parent>right_lower_shoulder</parent>
        <axis>
          <xyz>0.707105 -0.707108 0</xyz>
          <limit>
            <lower>-3.05418</lower>
            <upper>3.05418</upper>
            <effort>50</effort>
            <velocity>1.5</velocity>
          </limit>
          <dynamics>
            <damping>0.7</damping>
          </dynamics>
        </axis>
        <physics>
          <ode>
            <implicit_spring_damper>1</implicit_spring_damper>
            <cfm_damping>1</cfm_damping>
            <limit>
              <cfm>0</cfm>
              <erp>0.2</erp>
            </limit>
          </ode>
        </physics>
      </joint>
      <link name='right_lower_elbow'>
        <pose>0.370501 -0.565502 0.330976 -1.5708 1.76183e-17 -0.7854</pose>
        <inertial>
          <pose>0.026113 0.00158992 -0.0111695 0 -0 0</pose>
          <mass>2.07216</mass>
          <inertia>
            <ixx>0.00711585</ixx>
            <ixy>0.000360372</ixy>
            <ixz>0.00074588</ixz>
            <iyy>0.0131827</iyy>
            <iyz>-0.000196632</iyz>
            <izz>0.00926891</izz>
          </inertia>
        </inertial>
        <collision name='right_lower_elbow_collision'>
          <pose>0 0 0 0 -0 0</pose>
          <geometry>
            <cylinder>
              <length>0.1</length>
              <radius>0.06</radius>
            </cylinder>
          </geometry>
          <max_contacts>10</max_contacts>
          <surface>
            <bounce/>
            <friction>
              <ode/>
            </friction>
            <contact>
              <ode/>
            </contact>
          </surface>
        </collision>
        <collision name='right_lower_elbow_collision_right_upper_forearm_visual'>
          <pose>0.224 -6.65935e-13 6.6594e-13 1.5708 -1.69705e-16 1.5708</pose>
          <geometry>
            <cylinder>
              <length>0.272</length>
              <radius>0.06</radius>
            </cylinder>
          </geometry>
          <max_contacts>10</max_contacts>
          <surface>
            <bounce/>
            <friction>
              <ode/>
            </friction>
            <contact>
              <ode/>
            </contact>
          </surface>
        </collision>
        <visual name='right_lower_elbow_visual'>
          <pose>0 0 0 0 -0 0</pose>
          <geometry>
            <mesh>
              <scale>1 1 1</scale>
              <uri>/home/ynazon1/Desktop/baxter_stuff/src/baxter_common/baxter_description/meshes/lower_elbow/E1.DAE</uri>
            </mesh>
          </geometry>
        </visual>
        <velocity_decay>
          <linear>0</linear>
          <angular>0</angular>
        </velocity_decay>
        <self_collide>0</self_collide>
        <gravity>0</gravity>
        <kinematic>0</kinematic>
      </link>
      <joint name='right_e1' type='revolute'>
        <child>right_lower_elbow</child>
        <parent>right_upper_elbow</parent>
        <axis>
          <xyz>0.707108 0.707105 0</xyz>
          <limit>
            <lower>-0.05</lower>
            <upper>2.618</upper>
            <effort>50</effort>
            <velocity>1.5</velocity>
          </limit>
          <dynamics>
            <damping>0.7</damping>
          </dynamics>
        </axis>
        <physics>
          <ode>
            <implicit_spring_damper>1</implicit_spring_damper>
            <cfm_damping>1</cfm_damping>
            <limit>
              <cfm>0</cfm>
              <erp>0.2</erp>
            </limit>
          </ode>
        </physics>
      </joint>
      <link name='right_upper_forearm'>
        <pose>0.44375 -0.638751 0.330976 -2.03444 1.57079 -2.81984</pose>
        <inertial>
          <pose>-0.00168244 0.0045998 0.139519 0 -0 0</pose>
          <mass>2.24675</mass>
          <inertia>
            <ixx>0.0166775</ixx>
            <ixy>0.000184012</ixy>
            <ixz>0.000186469</ixz>
            <iyy>0.0167549</iyy>
            <iyz>-0.000647332</iyz>
            <izz>0.00374662</izz>
          </inertia>
        </inertial>
        <collision name='right_upper_forearm_collision'>
          <pose>0 0 -0.044 0 -0 0</pose>
          <geometry>
            <cylinder>
              <length>0.088</length>
              <radius>0.06</radius>
            </cylinder>
          </geometry>
          <max_contacts>10</max_contacts>
          <surface>
            <bounce/>
            <friction>
              <ode/>
            </friction>
            <contact>
              <ode/>
            </contact>
          </surface>
        </collision>
        <visual name='right_upper_forearm_visual'>
          <pose>0 0 0 0 -0 0</pose>
          <geometry>
            <mesh>
              <scale>1 1 1</scale>
              <uri>/home/ynazon1/Desktop/baxter_stuff/src/baxter_common/baxter_description/meshes/upper_forearm/W0.DAE</uri>
            </mesh>
          </geometry>
        </visual>
        <velocity_decay>
          <linear>0</linear>
          <angular>0</angular>
        </velocity_decay>
        <self_collide>0</self_collide>
        <gravity>0</gravity>
        <kinematic>0</kinematic>
      </link>
      <joint name='right_w0' type='revolute'>
        <child>right_upper_forearm</child>
        <parent>right_lower_elbow</parent>
        <axis>
          <xyz>0.707105 -0.707108 0</xyz>
          <limit>
            <lower>-3.059</lower>
            <upper>3.059</upper>
            <effort>15</effort>
            <velocity>4</velocity>
          </limit>
          <dynamics>
            <damping>0.7</damping>
          </dynamics>
        </axis>
        <physics>
          <ode>
            <implicit_spring_damper>1</implicit_spring_damper>
            <cfm_damping>1</cfm_damping>
            <limit>
              <cfm>0</cfm>
              <erp>0.2</erp>
            </limit>
          </ode>
        </physics>
      </joint>
      <link name='right_lower_forearm'>
        <pose>0.635163 -0.830166 0.320976 -1.5708 1.6263e-16 -0.7854</pose>
        <inertial>
          <pose>0.06041 0.00697 0.006 0 -0 0</pose>
          <mass>1.60979</mass>
          <inertia>
            <ixx>0.00387607</ixx>
            <ixy>-0.000443848</ixy>
            <ixz>-0.00021115</ixz>
            <iyy>0.00700538</iyy>
            <iyz>0.000153481</iyz>
            <izz>0.00552755</izz>
          </inertia>
        </inertial>
        <collision name='right_lower_forearm_collision'>
          <pose>0 0 0 0 -0 0</pose>
          <geometry>
            <cylinder>
              <length>0.1</length>
              <radius>0.06</radius>
            </cylinder>
          </geometry>
          <max_contacts>10</max_contacts>
          <surface>
            <bounce/>
            <friction>
              <ode/>
            </friction>
            <contact>
              <ode/>
            </contact>
          </surface>
        </collision>
        <visual name='right_lower_forearm_visual'>
          <pose>0 0 0 0 -0 0</pose>
          <geometry>
            <mesh>
              <scale>1 1 1</scale>
              <uri>/home/ynazon1/Desktop/baxter_stuff/src/baxter_common/baxter_description/meshes/lower_forearm/W1.DAE</uri>
            </mesh>
          </geometry>
        </visual>
        <velocity_decay>
          <linear>0</linear>
          <angular>0</angular>
        </velocity_decay>
        <self_collide>0</self_collide>
        <gravity>0</gravity>
        <kinematic>0</kinematic>
      </link>
      <joint name='right_w1' type='revolute'>
        <child>right_lower_forearm</child>
        <parent>right_upper_forearm</parent>
        <axis>
          <xyz>0.707108 0.707105 0</xyz>
          <limit>
            <lower>-1.5708</lower>
            <upper>2.094</upper>
            <effort>15</effort>
            <velocity>4</velocity>
          </limit>
          <dynamics>
            <damping>0.7</damping>
          </dynamics>
        </axis>
        <physics>
          <ode>
            <implicit_spring_damper>1</implicit_spring_damper>
            <cfm_damping>1</cfm_damping>
            <limit>
              <cfm>0</cfm>
              <erp>0.2</erp>
            </limit>
          </ode>
        </physics>
      </joint>
      <link name='right_wrist'>
        <pose>0.71717 -0.912173 0.320976 -1.89255 1.57079 -2.67795</pose>
        <inertial>
          <pose>0.00515172 0.000956882 0.0467434 0 -0 0</pose>
          <mass>0.54278</mass>
          <inertia>
            <ixx>0.00121873</ixx>
            <ixy>8.12598e-06</ixy>
            <ixz>-6.62108e-05</ixz>
            <iyy>0.00128054</iyy>
            <iyz>4.75609e-06</iyz>
            <izz>0.000555294</izz>
          </inertia>
        </inertial>
        <collision name='right_wrist_collision'>
          <pose>0 0 0 0 -0 0</pose>
          <geometry>
            <cylinder>
              <length>0.165</length>
              <radius>0.06</radius>
            </cylinder>
          </geometry>
          <max_contacts>10</max_contacts>
          <surface>
            <bounce/>
            <friction>
              <ode/>
            </friction>
            <contact>
              <ode/>
            </contact>
          </surface>
        </collision>
        <collision name='right_wrist_collision_right_hand'>
          <pose>0 0 0.09035 0 -0 0</pose>
          <geometry>
            <cylinder>
              <length>0.0464</length>
              <radius>0.04</radius>
            </cylinder>
          </geometry>
          <max_contacts>10</max_contacts>
          <surface>
            <bounce/>
            <friction>
              <ode/>
            </friction>
            <contact>
              <ode/>
            </contact>
          </surface>
        </collision>
        <visual name='right_wrist_visual'>
          <pose>0 0 0 0 -0 0</pose>
          <geometry>
            <mesh>
              <scale>1 1 1</scale>
              <uri>/home/ynazon1/Desktop/baxter_stuff/src/baxter_common/baxter_description/meshes/wrist/W2.DAE</uri>
            </mesh>
          </geometry>
        </visual>
        <visual name='right_wrist_visual_right_gripper'>
          <pose>0 0 0.13855 0 -0 0</pose>
          <geometry>
            <box>
              <size>0.01 0.01 0.01</size>
            </box>
          </geometry>
        </visual>
        <visual name='right_wrist_visual_right_gripper_base'>
          <pose>0 0 0.09355 0 -0 0</pose>
          <geometry>
            <box>
              <size>0.025 0.075 0.035</size>
            </box>
          </geometry>
        </visual>
        <visual name='right_wrist_visual_right_hand_accelerometer'>
          <pose>0.00198 0.000133 0.09895 0 -0 0</pose>
          <geometry>
            <box>
              <size>0.01 0.01 0.01</size>
            </box>
          </geometry>
        </visual>
        <visual name='right_wrist_visual_right_hand_camera'>
          <pose>0.03825 0.012 0.128905 0 0 -1.5708</pose>
          <geometry>
            <cylinder>
              <length>0.01</length>
              <radius>0.02</radius>
            </cylinder>
          </geometry>
        </visual>
        <visual name='right_wrist_visual_right_hand_range'>
          <pose>0.032 -0.020245 0.14235 -3.14158 -1.57079 1.57078</pose>
          <geometry>
            <box>
              <size>0.005 0.02 0.005</size>
            </box>
          </geometry>
        </visual>
        <velocity_decay>
          <linear>0</linear>
          <angular>0</angular>
        </velocity_decay>
        <sensor name='right_hand_camera' type='camera'>
          <update_rate>30</update_rate>
          <camera name='right_hand_camera'>
            <pose>0 0 0 2.65359e-06 -1.57079 1.57079</pose>
            <horizontal_fov>1.39626</horizontal_fov>
            <image>
              <width>800</width>
              <height>800</height>
              <format>R8G8B8</format>
            </image>
            <clip>
              <near>0.02</near>
              <far>300</far>
            </clip>
            <noise>
              <type>gaussian</type>
              <mean>0</mean>
              <stddev>0.007</stddev>
            </noise>
          </camera>
          <plugin name='camera_controller' filename='libgazebo_ros_camera.so'>
            <alwaysOn>true</alwaysOn>
            <updateRate>0.0</updateRate>
            <cameraName>right_hand_camera</cameraName>
            <imageTopicName>image</imageTopicName>
            <cameraInfoTopicName>camera_info</cameraInfoTopicName>
            <frameName>right_hand_camera</frameName>
            <hackBaseline>0.07</hackBaseline>
            <distortionK1>0.0</distortionK1>
            <distortionK2>0.0</distortionK2>
            <distortionK3>0.0</distortionK3>
            <distortionT1>0.0</distortionT1>
            <distortionT2>0.0</distortionT2>
            <robotNamespace>/cameras</robotNamespace>
          </plugin>
          <pose>0.03825 0.012 0.128905 0 0 -1.5708</pose>
        </sensor>
        <gravity>0</gravity>
        <velocity_decay>
          <linear>0</linear>
          <angular>0</angular>
        </velocity_decay>
        <self_collide>0</self_collide>
        <sensor name='ir_right' type='ray'>
          <ray>
            <scan>
              <horizontal>
                <samples>1</samples>
                <resolution>1</resolution>
                <min_angle>-0.5</min_angle>
                <max_angle>0.5</max_angle>
              </horizontal>
            </scan>
            <range>
              <min>0.004</min>
              <max>0.4</max>
            </range>
          </ray>
          <plugin name='plugin_3' filename='libgazebo_ros_laser.so'>
            <gaussianNoise>0.005</gaussianNoise>
            <alwaysOn>true</alwaysOn>
            <updateRate>100</updateRate>
            <topicName>/sim/laserscan/right_hand_range/state</topicName>
            <frameName>right_hand_range</frameName>
            <robotNamespace>/</robotNamespace>
          </plugin>
          <always_on>1</always_on>
          <update_rate>100</update_rate>
          <pose>0.032 -0.020245 0.14235 -3.14158 -1.57079 1.57078</pose>
        </sensor>
        <kinematic>0</kinematic>
      </link>
      <joint name='right_w2' type='revolute'>
        <child>right_wrist</child>
        <parent>right_lower_forearm</parent>
        <axis>
          <xyz>0.707105 -0.707108 0</xyz>
          <limit>
            <lower>-3.059</lower>
            <upper>3.059</upper>
            <effort>15</effort>
            <velocity>4</velocity>
          </limit>
          <dynamics>
            <damping>0.7</damping>
          </dynamics>
        </axis>
        <physics>
          <ode>
            <implicit_spring_damper>1</implicit_spring_damper>
            <cfm_damping>1</cfm_damping>
            <limit>
              <cfm>0</cfm>
              <erp>0.2</erp>
            </limit>
          </ode>
        </physics>
      </joint>
      <static>0</static>
      <plugin name='baxter_ros_control' filename='libbaxter_gazebo_ros_control.so'>
        <robotNamespace>/robot</robotNamespace>
      </plugin>
      <pose>0 0 0.93 0 -0 0</pose>
    </model>
    <model name='table'>
      <static>1</static>
      <link name='link'>
        <collision name='surface'>
          <pose>0 0 1 0 -0 0</pose>
          <geometry>
            <box>
              <size>1.5 0.8 0.03</size>
            </box>
          </geometry>
          <surface>
            <friction>
              <ode>
                <mu>0.6</mu>
                <mu2>0.6</mu2>
              </ode>
            </friction>
            <bounce/>
            <contact>
              <ode/>
            </contact>
          </surface>
          <max_contacts>10</max_contacts>
        </collision>
        <visual name='visual1'>
          <pose>0 0 1 0 -0 0</pose>
          <geometry>
            <box>
              <size>1.5 0.8 0.03</size>
            </box>
          </geometry>
          <material>
            <script>
              <uri>file://media/materials/scripts/gazebo.material</uri>
              <name>Gazebo/Wood</name>
            </script>
          </material>
        </visual>
        <collision name='front_left_leg'>
          <pose>0.68 0.38 0.5 0 -0 0</pose>
          <geometry>
            <cylinder>
              <radius>0.02</radius>
              <length>1</length>
            </cylinder>
          </geometry>
          <max_contacts>10</max_contacts>
          <surface>
            <bounce/>
            <friction>
              <ode/>
            </friction>
            <contact>
              <ode/>
            </contact>
          </surface>
        </collision>
        <visual name='front_left_leg'>
          <pose>0.68 0.38 0.5 0 -0 0</pose>
          <geometry>
            <cylinder>
              <radius>0.02</radius>
              <length>1</length>
            </cylinder>
          </geometry>
          <material>
            <script>
              <uri>file://media/materials/scripts/gazebo.material</uri>
              <name>Gazebo/Grey</name>
            </script>
          </material>
        </visual>
        <collision name='front_right_leg'>
          <pose>0.68 -0.38 0.5 0 -0 0</pose>
          <geometry>
            <cylinder>
              <radius>0.02</radius>
              <length>1</length>
            </cylinder>
          </geometry>
          <max_contacts>10</max_contacts>
          <surface>
            <bounce/>
            <friction>
              <ode/>
            </friction>
            <contact>
              <ode/>
            </contact>
          </surface>
        </collision>
        <visual name='front_right_leg'>
          <pose>0.68 -0.38 0.5 0 -0 0</pose>
          <geometry>
            <cylinder>
              <radius>0.02</radius>
              <length>1</length>
            </cylinder>
          </geometry>
          <material>
            <script>
              <uri>file://media/materials/scripts/gazebo.material</uri>
              <name>Gazebo/Grey</name>
            </script>
          </material>
        </visual>
        <collision name='back_right_leg'>
          <pose>-0.68 -0.38 0.5 0 -0 0</pose>
          <geometry>
            <cylinder>
              <radius>0.02</radius>
              <length>1</length>
            </cylinder>
          </geometry>
          <max_contacts>10</max_contacts>
          <surface>
            <bounce/>
            <friction>
              <ode/>
            </friction>
            <contact>
              <ode/>
            </contact>
          </surface>
        </collision>
        <visual name='back_right_leg'>
          <pose>-0.68 -0.38 0.5 0 -0 0</pose>
          <geometry>
            <cylinder>
              <radius>0.02</radius>
              <length>1</length>
            </cylinder>
          </geometry>
          <material>
            <script>
              <uri>file://media/materials/scripts/gazebo.material</uri>
              <name>Gazebo/Grey</name>
            </script>
          </material>
        </visual>
        <collision name='back_left_leg'>
          <pose>-0.68 0.38 0.5 0 -0 0</pose>
          <geometry>
            <cylinder>
              <radius>0.02</radius>
              <length>1</length>
            </cylinder>
          </geometry>
          <max_contacts>10</max_contacts>
          <surface>
            <bounce/>
            <friction>
              <ode/>
            </friction>
            <contact>
              <ode/>
            </contact>
          </surface>
        </collision>
        <visual name='back_left_leg'>
          <pose>-0.68 0.38 0.5 0 -0 0</pose>
          <geometry>
            <cylinder>
              <radius>0.02</radius>
              <length>1</length>
            </cylinder>
          </geometry>
          <material>
            <script>
              <uri>file://media/materials/scripts/gazebo.material</uri>
              <name>Gazebo/Grey</name>
            </script>
          </material>
        </visual>
        <velocity_decay>
          <linear>0</linear>
          <angular>0</angular>
        </velocity_decay>
        <self_collide>0</self_collide>
        <kinematic>0</kinematic>
        <gravity>1</gravity>
      </link>
      <pose>3 -1 0 0 -0 0</pose>
    </model>
    <model name='wood_cube_5cm'>
      <link name='link'>
        <pose>0 0 0.025 0 -0 0</pose>
        <inertial>
          <mass>0.0565</mass>
          <inertia>
            <ixx>2.35417e-05</ixx>
            <ixy>0</ixy>
            <ixz>0</ixz>
            <iyy>2.35417e-05</iyy>
            <iyz>0</iyz>
            <izz>2.35417e-05</izz>
          </inertia>
        </inertial>
        <collision name='collision'>
          <geometry>
            <box>
              <size>0.05 0.05 0.05</size>
            </box>
          </geometry>
          <surface>
            <contact>
              <ode>
                <max_vel>0.1</max_vel>
                <min_depth>0.001</min_depth>
              </ode>
            </contact>
            <bounce/>
            <friction>
              <ode/>
            </friction>
          </surface>
          <max_contacts>10</max_contacts>
        </collision>
        <visual name='visual'>
          <geometry>
            <box>
              <size>0.05 0.05 0.05</size>
            </box>
          </geometry>
          <material>
            <script>
              <uri>file://media/materials/scripts/gazebo.material</uri>
              <name>Gazebo/Wood</name>
            </script>
          </material>
        </visual>
        <velocity_decay>
          <linear>0</linear>
          <angular>0</angular>
        </velocity_decay>
        <self_collide>0</self_collide>
        <kinematic>0</kinematic>
        <gravity>1</gravity>
      </link>
      <pose>1.4234 -0.583761 0 0 -0 0</pose>
      <static>0</static>
    </model>
    <model name='wood_cube_5cm_0'>
      <link name='link'>
        <pose>0 0 0.025 0 -0 0</pose>
        <inertial>
          <mass>0.0565</mass>
          <inertia>
            <ixx>2.35417e-05</ixx>
            <ixy>0</ixy>
            <ixz>0</ixz>
            <iyy>2.35417e-05</iyy>
            <iyz>0</iyz>
            <izz>2.35417e-05</izz>
          </inertia>
        </inertial>
        <collision name='collision'>
          <geometry>
            <box>
              <size>0.05 0.05 0.05</size>
            </box>
          </geometry>
          <surface>
            <contact>
              <ode>
                <max_vel>0.1</max_vel>
                <min_depth>0.001</min_depth>
              </ode>
            </contact>
            <bounce/>
            <friction>
              <ode/>
            </friction>
          </surface>
          <max_contacts>10</max_contacts>
        </collision>
        <visual name='visual'>
          <geometry>
            <box>
              <size>0.05 0.05 0.05</size>
            </box>
          </geometry>
          <material>
            <script>
              <uri>file://media/materials/scripts/gazebo.material</uri>
              <name>Gazebo/Wood</name>
            </script>
          </material>
        </visual>
        <velocity_decay>
          <linear>0</linear>
          <angular>0</angular>
        </velocity_decay>
        <self_collide>0</self_collide>
        <kinematic>0</kinematic>
        <gravity>1</gravity>
      </link>
      <pose>1 -0.572277 0 0 -0 0</pose>
      <static>0</static>
    </model>
    <model name='wood_cube_5cm_1'>
      <link name='link'>
        <pose>0 0 0.025 0 -0 0</pose>
        <inertial>
          <mass>0.0565</mass>
          <inertia>
            <ixx>2.35417e-05</ixx>
            <ixy>0</ixy>
            <ixz>0</ixz>
            <iyy>2.35417e-05</iyy>
            <iyz>0</iyz>
            <izz>2.35417e-05</izz>
          </inertia>
        </inertial>
        <collision name='collision'>
          <geometry>
            <box>
              <size>0.05 0.05 0.05</size>
            </box>
          </geometry>
          <surface>
            <contact>
              <ode>
                <max_vel>0.1</max_vel>
                <min_depth>0.001</min_depth>
              </ode>
            </contact>
            <bounce/>
            <friction>
              <ode/>
            </friction>
          </surface>
          <max_contacts>10</max_contacts>
        </collision>
        <visual name='visual'>
          <geometry>
            <box>
              <size>0.05 0.05 0.05</size>
            </box>
          </geometry>
          <material>
            <script>
              <uri>file://media/materials/scripts/gazebo.material</uri>
              <name>Gazebo/Wood</name>
            </script>
          </material>
        </visual>
        <velocity_decay>
          <linear>0</linear>
          <angular>0</angular>
        </velocity_decay>
        <self_collide>0</self_collide>
        <kinematic>0</kinematic>
        <gravity>1</gravity>
      </link>
      <pose>1 -1 0 0 -0 0</pose>
      <static>0</static>
    </model>
    <model name='wood_cube_5cm_2'>
      <link name='link'>
        <pose>0 0 0.025 0 -0 0</pose>
        <inertial>
          <mass>0.0565</mass>
          <inertia>
            <ixx>2.35417e-05</ixx>
            <ixy>0</ixy>
            <ixz>0</ixz>
            <iyy>2.35417e-05</iyy>
            <iyz>0</iyz>
            <izz>2.35417e-05</izz>
          </inertia>
        </inertial>
        <collision name='collision'>
          <geometry>
            <box>
              <size>0.05 0.05 0.05</size>
            </box>
          </geometry>
          <surface>
            <contact>
              <ode>
                <max_vel>0.1</max_vel>
                <min_depth>0.001</min_depth>
              </ode>
            </contact>
            <bounce/>
            <friction>
              <ode/>
            </friction>
          </surface>
          <max_contacts>10</max_contacts>
        </collision>
        <visual name='visual'>
          <geometry>
            <box>
              <size>0.05 0.05 0.05</size>
            </box>
          </geometry>
          <material>
            <script>
              <uri>file://media/materials/scripts/gazebo.material</uri>
              <name>Gazebo/Green</name>
            </script>
          </material>
        </visual>
        <velocity_decay>
          <linear>0</linear>
          <angular>0</angular>
        </velocity_decay>
        <self_collide>0</self_collide>
        <kinematic>0</kinematic>
        <gravity>1</gravity>
      </link>
      <pose>1 -1 0 0 -0 0</pose>
      <static>0</static>
    </model>
    <model name='cricket_ball'>
      <link name='link'>
        <pose>0 0 0.0375 0 -0 0</pose>
        <inertial>
          <mass>0.1467</mass>
          <inertia>
            <ixx>8.25187e-05</ixx>
            <ixy>0</ixy>
            <ixz>0</ixz>
            <iyy>8.25187e-05</iyy>
            <iyz>0</iyz>
            <izz>8.25187e-05</izz>
          </inertia>
        </inertial>
        <collision name='collision'>
          <geometry>
            <sphere>
              <radius>0.0375</radius>
            </sphere>
          </geometry>
          <max_contacts>10</max_contacts>
          <surface>
            <bounce/>
            <friction>
              <ode/>
            </friction>
            <contact>
              <ode/>
            </contact>
          </surface>
        </collision>
        <visual name='visual'>
          <geometry>
            <sphere>
              <radius>0.0375</radius>
            </sphere>
          </geometry>
          <material>
            <script>
              <uri>file://media/materials/scripts/gazebo.material</uri>
              <name>Gazebo/Red</name>
            </script>
          </material>
        </visual>
        <velocity_decay>
          <linear>0</linear>
          <angular>0.005</angular>
        </velocity_decay>
        <self_collide>0</self_collide>
        <kinematic>0</kinematic>
        <gravity>1</gravity>
      </link>
      <pose>0 -1.52431 0 0 -0 0</pose>
      <static>0</static>
    </model>
    <state world_name='default'>
      <sim_time>259 902000000</sim_time>
      <real_time>605 465886576</real_time>
      <wall_time>1449183679 250424128</wall_time>
      <model name='baxter'>
        <pose>0.12347 -0.249517 0.92418 1.08697e-23 1e-06 -0.087357</pose>
        <link name='base'>
          <pose>0.12347 -0.249517 0.92418 1.08697e-23 1e-06 -0.087357</pose>
          <velocity>0.001629 -0.000219 5.7e-05 0.000265 0.001774 4.8e-05</velocity>
          <acceleration>3.13572 -0.292424 0.044946 0.022695 0.274366 0.011456</acceleration>
          <wrench>301.66 -28.1315 4.32384 0 -0 0</wrench>
        </link>
        <link name='head'>
          <pose>0.183241 -0.254752 1.61018 0 -0 -0.088757</pose>
          <velocity>0.003017 -0.000365 -4.3e-05 0.000238 0.002036 0.000595</velocity>
          <acceleration>5.46502 -0.416 -0.351527 0.002062 0.037759 -0.003962</acceleration>
          <wrench>5.40074 -0.411107 -0.347392 0 -0 0</wrench>
        </link>
        <link name='left_lower_elbow'>
          <pose>0.516367 -0.055344 1.59408 -1.119 0.627779 0.534193</pose>
          <velocity>0.000695 -0.000162 0.001334 -0.00382 0.00366 0.003372</velocity>
          <acceleration>1.08101 -0.409833 2.18472 -0.018045 0.036704 0.022108</acceleration>
          <wrench>2.24003 -0.84924 4.5271 0 -0 0</wrench>
        </link>
        <link name='left_lower_forearm'>
          <pose>0.826128 -0.000753 1.35875 -2.48299 1.49996 2.72412</pose>
          <velocity>-0.000395 -6e-05 -0.000101 0.001892 -0.002152 0.001295</velocity>
          <acceleration>-0.450782 0.044793 -0.142676 0.008179 -0.016204 0.007258</acceleration>
          <wrench>-0.725664 0.072108 -0.229678 0 -0 0</wrench>
        </link>
        <link name='left_lower_shoulder'>
          <pose>0.275413 -0.018062 1.32447 -1.5708 -0.957522 -0.309961</pose>
          <velocity>0.002337 -0.000419 -0.00016 -0.002111 -0.005698 -0.00152</velocity>
          <acceleration>3.68508 -0.593208 0.031117 -0.014995 -0.058322 -0.03368</acceleration>
          <wrench>11.8921 -1.91433 0.100416 0 -0 0</wrench>
        </link>
        <link name='left_upper_elbow'>
          <pose>0.321574 -0.036259 1.41435 0.407846 0.471609 0.450363</pose>
          <velocity>0.001803 -0.000322 0.000144 -0.001321 -0.005931 -0.000371</velocity>
          <acceleration>1.6007 -0.330528 1.2621 -0.012988 -0.071273 -0.007081</acceleration>
          <wrench>6.90338 -1.42548 5.44307 0 -0 0</wrench>
        </link>
        <link name='left_upper_forearm'>
          <pose>0.633564 -0.114298 1.51534 -3.04659 -0.939729 0.416722</pose>
          <velocity>0.000526 -0.000115 0.001 -0.001862 0.004815 0.001731</velocity>
          <acceleration>0.064784 -0.24815 0.750897 -0.023614 0.059393 0.002821</acceleration>
          <wrench>0.145553 -0.557532 1.68708 0 -0 0</wrench>
        </link>
        <link name='left_upper_shoulder'>
          <pose>0.209852 0.002937 1.05381 -5.82516e-23 1e-06 -0.309961</pose>
          <velocity>0.00188 -0.000247 -4.5e-05 0.000265 0.001713 -0.001491</velocity>
          <acceleration>4.12594 -0.418407 -0.262832 -0.007814 0.010647 -0.025516</acceleration>
          <wrench>23.5196 -2.38511 -1.49826 0 -0 0</wrench>
        </link>
        <link name='left_wrist'>
          <pose>0.757381 0.184389 1.25226 3.10839 -0.062585 -3.07097</pose>
          <velocity>-0.000148 8.1e-05 8.5e-05 0.001721 -0.002071 -0.001345</velocity>
          <acceleration>-0.082335 0.220494 0.12168 0.006815 -0.00853 -0.002149</acceleration>
          <wrench>-0.04469 0.11968 0.066046 0 -0 0</wrench>
        </link>
        <link name='right_lower_elbow'>
          <pose>0.443942 -0.84406 1.25362 -1.56904 0.000992 -0.870063</pose>
          <velocity>0.00116 -0.000549 -0.000364 0.00149 -0.005506 -0.003178</velocity>
          <acceleration>2.11218 -1.2349 -0.713353 0.005886 -0.063877 -0.028688</acceleration>
          <wrench>4.37677 -2.55892 -1.47818 0 -0 0</wrench>
        </link>
        <link name='right_lower_forearm'>
          <pose>0.685261 -1.13005 1.2432 -1.57096 -0.001083 -0.870063</pose>
          <velocity>0.000156 -0.000963 3.2e-05 -0.005402 -0.001484 -0.003339</velocity>
          <acceleration>0.203061 -2.31361 0.599203 -0.023063 -0.006485 -0.019969</acceleration>
          <wrench>0.326885 -3.72442 0.964591 0 -0 0</wrench>
        </link>
        <link name='right_lower_shoulder'>
          <pose>0.209145 -0.565884 1.32415 -1.5708 0.004338 -0.870056</pose>
          <velocity>0.002075 -0.000234 -0.000167 -0.000453 0.001353 -0.003063</velocity>
          <acceleration>3.73219 -0.647544 -0.365598 -0.006168 0.025122 -0.043946</acceleration>
          <wrench>12.0441 -2.08968 -1.17981 0 -0 0</wrench>
        </link>
        <link name='right_upper_elbow'>
          <pose>0.274901 -0.643857 1.32373 2.75772 1.56611 1.88766</pose>
          <velocity>0.001678 -0.000434 -0.000136 0.004143 -0.003556 -0.003086</velocity>
          <acceleration>2.45997 -1.6286 -0.579977 0.041174 -0.046487 -0.014261</acceleration>
          <wrench>10.6092 -7.02372 -2.50128 0 -0 0</wrench>
        </link>
        <link name='right_upper_forearm'>
          <pose>0.51078 -0.923202 1.25345 -2.97384 1.56979 2.43928</pose>
          <velocity>0.000996 -0.000556 -0.000444 -0.003129 0.000812 -0.003141</velocity>
          <acceleration>1.35799 -1.72692 -0.386383 -0.044553 0.010638 -0.01119</acceleration>
          <wrench>3.05107 -3.87996 -0.868106 0 -0 0</wrench>
        </link>
        <link name='right_upper_shoulder'>
          <pose>0.164654 -0.513142 1.05381 1e-06 -1.96197e-23 -0.870056</pose>
          <velocity>0.001625 3.7e-05 -4.5e-05 0.000606 0.002615 -0.003029</velocity>
          <acceleration>4.12709 -0.163215 -0.165331 -0.001224 0.02582 -0.037512</acceleration>
          <wrench>23.5262 -0.930396 -0.942457 0 -0 0</wrench>
        </link>
        <link name='right_wrist'>
          <pose>0.76012 -1.21863 1.24316 -1.18729 1.56791 -2.05736</pose>
          <velocity>0.000229 -0.000764 -0.000263 -0.013453 0.008594 -0.00371</velocity>
          <acceleration>0.247433 -2.00047 0.017166 -0.046811 0.027463 -0.004316</acceleration>
          <wrench>0.134301 -1.08581 0.009317 0 -0 0</wrench>
        </link>
      </model>
      <model name='cricket_ball'>
        <pose>0.990005 -0.928446 1.01815 -0.378094 0.170008 0.11628</pose>
        <link name='link'>
          <pose>0.994255 -0.914012 1.0525 -0.378094 0.170008 0.11628</pose>
          <velocity>0 0 0 0 -0 0</velocity>
          <acceleration>-0 2e-06 -0 0 -0 0</acceleration>
          <wrench>-0 0 -0 0 -0 0</wrench>
        </link>
      </model>
      <model name='ground_plane'>
        <pose>0 0 0 0 -0 0</pose>
        <link name='link'>
          <pose>0 0 0 0 -0 0</pose>
          <velocity>0 0 0 0 -0 0</velocity>
          <acceleration>0 0 0 0 -0 0</acceleration>
          <wrench>0 0 0 0 -0 0</wrench>
        </link>
      </model>
      <model name='table'>
        <pose>0.91778 -0.42075 0 0 0 -1.58572</pose>
        <link name='link'>
          <pose>0.91778 -0.42075 0 0 0 -1.58572</pose>
          <velocity>0 0 0 0 -0 0</velocity>
          <acceleration>0 0 0 0 -0 0</acceleration>
          <wrench>0 0 0 0 -0 0</wrench>
        </link>
      </model>
      <model name='unit_box_2'>
        <pose>0.809211 -0.808343 1.04557 0.000111 -0.00043 -1.8e-05</pose>
        <link name='link'>
          <pose>0.809211 -0.808343 1.04557 0.000111 -0.00043 -1.8e-05</pose>
          <velocity>0 0 0 0 -0 0</velocity>
          <acceleration>0.027463 0.024259 19.5707 -0.793093 0.899584 -1e-06</acceleration>
          <wrench>0.027463 0.024259 19.5707 0 -0 0</wrench>
        </link>
      </model>
      <model name='wood_cube_5cm'>
        <pose>0.681198 0.169128 1.01497 0.00081 -1.4e-05 0.011724</pose>
        <link name='link'>
          <pose>0.681198 0.169107 1.03997 0.00081 -1.4e-05 0.011724</pose>
          <velocity>0 0 0 0 -0 0</velocity>
          <acceleration>0 0 -0 0 -0 0</acceleration>
          <wrench>0 0 -0 0 -0 0</wrench>
        </link>
      </model>
      <model name='wood_cube_5cm_0'>
        <pose>0.825105 -1.02415 1.015 -5.1e-05 5.1e-05 -6e-06</pose>
        <link name='link'>
          <pose>0.825106 -1.02415 1.04 -5.1e-05 5.1e-05 -6e-06</pose>
          <velocity>0 0 0 0 -0 0</velocity>
          <acceleration>0 0 -0 0 -0 0</acceleration>
          <wrench>0 0 -0 0 -0 0</wrench>
        </link>
      </model>
      <model name='wood_cube_5cm_1'>
        <pose>0.801906 -0.913217 1.03976 1.56854 -1.56518 1.57299</pose>
        <link name='link'>
          <pose>0.826906 -0.913218 1.03976 1.56854 -1.56518 1.57299</pose>
          <velocity>0 0 0 0 -0 0</velocity>
          <acceleration>-0 0 -0 0 -0 0</acceleration>
          <wrench>-0 0 -0 0 -0 0</wrench>
        </link>
      </model>
      <model name='wood_cube_5cm_2'>
        <pose>0.89156 -0.979158 1.01483 0.003669 -9.6e-05 0.014864</pose>
        <link name='link'>
          <pose>0.891559 -0.97925 1.03983 0.003669 -9.6e-05 0.014864</pose>
          <velocity>0 0 0 0 -0 0</velocity>
          <acceleration>0 -0 -0 0 -0 0</acceleration>
          <wrench>0 -0 -0 0 -0 0</wrench>
        </link>
      </model>
    </state>
    <gui fullscreen='0'>
      <camera name='user_camera'>
        <pose>4.06098 -3.60724 2.53604 1.00491e-17 0.275643 2.35619</pose>
        <view_controller>orbit</view_controller>
      </camera>
    </gui>
    <model name='unit_box_2'>
      <pose>-1 -1.49777 0.5 0 -0 0</pose>
      <link name='link'>
        <inertial>
          <mass>1</mass>
          <inertia>
            <ixx>1</ixx>
            <ixy>0</ixy>
            <ixz>0</ixz>
            <iyy>1</iyy>
            <iyz>0</iyz>
            <izz>1</izz>
          </inertia>
        </inertial>
        <collision name='collision'>
          <geometry>
            <box>
              <size>0.061317 0.054046 0.061108</size>
            </box>
          </geometry>
          <max_contacts>10</max_contacts>
          <surface>
            <bounce/>
            <friction>
              <ode/>
            </friction>
            <contact>
              <ode/>
            </contact>
          </surface>
        </collision>
        <visual name='visual'>
          <geometry>
            <box>
              <size>1 1 1</size>
            </box>
          </geometry>
          <material>
            <script>
              <uri>file://media/materials/scripts/gazebo.material</uri>
              <name>Gazebo/Grey</name>
            </script>
          </material>
        </visual>
        <velocity_decay>
          <linear>0</linear>
          <angular>0</angular>
        </velocity_decay>
        <self_collide>0</self_collide>
        <kinematic>0</kinematic>
        <gravity>1</gravity>
      </link>
      <static>0</static>
    </model>
  </world>
</sdf>
